<?xml version='1.0' encoding='utf-8'?>
<sdf version="1.6">
  <world name='empty'>
    <physics name='1ms' type='ode'>  
      <max_step_size>0.001</max_step_size>
      <real_time_factor>1</real_time_factor>
      <real_time_update_rate>1000</real_time_update_rate>
    </physics>
    <plugin name='gz::sim::systems::Physics' filename='ignition-gazebo-physics-system'/>
    <plugin name='gz::sim::systems::UserCommands' filename='ignition-gazebo-user-commands-system'/>
    <plugin name='gz::sim::systems::SceneBroadcaster' filename='ignition-gazebo-scene-broadcaster-system'/>
    <plugin name='gz::sim::systems::Contact' filename='ignition-gazebo-contact-system'/>
    <plugin filename="libignition-gazebo-imu-system.so"
        name="ignition::gazebo::systems::Imu">
    </plugin>
    <plugin
      filename="ignition-gazebo-sensors-system"
      name="ignition::gazebo::systems::Sensors">
      <render_engine>ogre2</render_engine>
    </plugin>
        <gui fullscreen='false'>
      <plugin name='3D View' filename='GzScene3D'>
        <ignition-gui>
          <title>3D View</title>
          <property type='bool' key='showTitleBar'>false</property>
          <property type='string' key='state'>docked</property>
        </ignition-gui>
        <engine>ogre2</engine>
        <scene>scene</scene>
        <ambient_light>0.4 0.4 0.4</ambient_light>
        <background_color>0.5 0.8 0.95</background_color>
        <camera_follow>
          <target>prius_hybrid</target>
          <p_gain>0.5</p_gain>
          <offset>0.5 5 2</offset>
        </camera_follow>
      </plugin>

      <plugin filename="InteractiveViewControl" name="Interactive view control">
        <ignition-gui>
          <property key="resizable" type="bool">false</property>
          <property key="width" type="double">5</property>
          <property key="height" type="double">5</property>
          <property key="state" type="string">floating</property>
          <property key="showTitleBar" type="bool">false</property>
        </ignition-gui>
      </plugin>

      <plugin name='World control' filename='WorldControl'>
        <ignition-gui>
          <title>World control</title>
          <property type='bool' key='showTitleBar'>false</property>
          <property type='bool' key='resizable'>false</property>
          <property type='double' key='height'>72</property>
          <property type='double' key='width'>121</property>
          <property type='double' key='z'>1</property>
          <property type='string' key='state'>floating</property>
          <anchors target='3D View'>
            <line own='left' target='left'/>
            <line own='bottom' target='bottom'/>
          </anchors>
        </ignition-gui>
        <play_pause>true</play_pause>
        <step>true</step>
        <start_paused>true</start_paused>
      </plugin>
      <plugin name='World stats' filename='WorldStats'>
        <ignition-gui>
          <title>World stats</title>
          <property type='bool' key='showTitleBar'>false</property>
          <property type='bool' key='resizable'>false</property>
          <property type='double' key='height'>110</property>
          <property type='double' key='width'>290</property>
          <property type='double' key='z'>1</property>
          <property type='string' key='state'>floating</property>
          <anchors target='3D View'>
            <line own='right' target='right'/>
            <line own='bottom' target='bottom'/>
          </anchors>
        </ignition-gui>
        <sim_time>true</sim_time>
        <real_time>true</real_time>
        <real_time_factor>true</real_time_factor>
        <iterations>true</iterations>
      </plugin>
      <plugin name='dis' filename='ImageDisplay'>
        <ignition-gui>
          <property key='state' type='string'>docked</property>
        </ignition-gui>
        <topic>front_camera</topic>
      </plugin>
      <plugin name='Teleop' filename='Teleop'>
        <ignition-gui>
          <property type='string' key='state'>docked</property>
        </ignition-gui>
        <topic>/cmd_vel</topic>
      </plugin>
    
    <plugin filename="EntityTree" name="Entity tree">
    </plugin>

    <!-- <plugin filename="CameraTracking" name="Camera Tracking">
        <ignition-gui>
          <property key="resizable" type="bool">false</property>
          <property key="width" type="double">5</property>
          <property key="height" type="double">5</property>
          <property key="state" type="string">floating</property>
          <property key="showTitleBar" type="bool">false</property>
        </ignition-gui>
    </plugin> -->
    </gui>
    <gravity>0 0 -9.8</gravity>
    <magnetic_field>6e-06 2.3e-05 -4.2e-05</magnetic_field>
    <atmosphere type='adiabatic'/>
    <scene>
      <ambient>0.4 0.4 0.4 1</ambient>
      <background>0.7 0.7 0.7 1</background>
      <shadows>true</shadows>
    </scene>
    <model name='ground_plane'>
      <static>true</static>
      <link name='floor'>
        <collision name='collision'>
          <geometry>
            <plane>
              <normal>0 0 1</normal>
              <size>100 100</size>
            </plane>
          </geometry>
          <surface>
            <friction>
              <ode/>
            </friction>
            <bounce/>
            <contact/>
          </surface>
        </collision>
        <visual name='visual'>
          <geometry>
            <plane>
              <normal>0 0 1</normal>
              <size>100 100</size>
            </plane>
          </geometry>
          <material>
            <ambient>0.8 0.8 0.8 1</ambient>
            <diffuse>0.8 0.8 0.8 1</diffuse>
            <specular>0.8 0.8 0.8 1</specular>
          </material>
        </visual>
        <pose>0 0 0 0 -0 0</pose>
        <inertial>
          <pose>0 0 0 0 -0 0</pose>
          <mass>1</mass>
          <inertia>
            <ixx>1</ixx>
            <ixy>0</ixy>
            <ixz>0</ixz>
            <iyy>1</iyy>
            <iyz>0</iyz>
            <izz>1</izz>
          </inertia>
        </inertial>
        <enable_wind>false</enable_wind>
      </link>
          <link name="left_wall_seg1">
        <pose>1.0 0.5 0.5 0 0 0</pose>
        <visual name="visual">
          <geometry>
            <box><size>2.5 0.1 1</size></box>
          </geometry>
          <material>
            <ambient>0.7 0.7 0.7 1</ambient>
            <diffuse>0.7 0.7 0.7 1</diffuse>
          </material>
        </visual>
        <collision name="collision">
          <geometry>
            <box><size>2.5 0.1 1</size></box>
          </geometry>
        </collision>
      </link>
       <!-- ================================
           Segment 1: 2.5 m straight
           Orientation: 0° (along X-axis)
           Track width: 1 m
           Left & right walls
         ================================ -->

      <!-- Left Wall, Segment 1 -->
      <!-- Center of segment at x=1.25, offset +0.5 in y -->
      <link name="right_wall_seg1">
        <pose>1.0 -0.5 0.5 0 0 0</pose>
        <visual name="visual">
          <geometry>
            <box><size>3.0 0.1 1</size></box>
          </geometry>
          <material>
            <ambient>0.7 0.7 0.7 1</ambient>
            <diffuse>0.7 0.7 0.7 1</diffuse>
          </material>
        </visual>
        <collision name="collision">
          <geometry>
            <box><size>3.0 0.1 1</size></box>
          </geometry>
        </collision>
      </link>
    <!-- ================================
           Segment 2: 2.5 m straight
           Orientation: 45°
           Start pivot at (2.5, 0)
         ================================ -->

      <!-- For a 2.5 m segment at 45°:
           Center is pivot + 1.25*(cos 45, sin 45) => ~ (3.3839, 0.8839)
           Then offset ±0.5 perpendicular to that direction:
             Left offset => -0.3536, +0.3536
             Right offset => +0.3536, -0.3536
      -->

      <link name="left_wall_seg2">
        <pose>3.0003 1.2875 0.5 0 0 0.7854</pose>
        <visual name="visual">
          <geometry>
            <box><size>2.2 0.1 1</size></box>
          </geometry>
          <material>
            <ambient>0.7 0.7 0.7 1</ambient>
            <diffuse>0.7 0.7 0.7 1</diffuse>
          </material>
        </visual>
        <collision name="collision">
          <geometry>
            <box><size>2.2 0.1 1</size></box>
          </geometry>
        </collision>
      </link>

      <link name="right_wall_seg2">
        <pose>3.6625 0.6053 0.5 0 0 0.7854</pose>
        <visual name="visual">
          <geometry>
            <box><size>3.25 0.1 1</size></box>
          </geometry>
          <material>
            <ambient>0.7 0.7 0.7 1</ambient>
            <diffuse>0.7 0.7 0.7 1</diffuse>
          </material>
        </visual>
        <collision name="collision">
          <geometry>
            <box><size>3.25 0.1 1</size></box>
          </geometry>
        </collision>
      </link>

      <!-- ================================
           Segment 3: 2.5 m straight
           Orientation: 90° (45° more)
           Start pivot at end of Segment 2
         ================================ -->

      <!-- End of seg2 is pivot + 2.5*(cos 45, sin 45) => ~ (4.2678, 1.7678)
           Center is pivot + 1.25*(cos 90, sin 90) => + (0, 1.25)
           => (4.2678, 3.0178)
           Then offset ±0.5 perpendicular to 90°:
             Left => (-0.5, 0)
             Right => (+0.5, 0)
      -->
      <link name="left_wall_seg3">
        <pose>3.7678 3.2678 0.5 0 0 1.5708</pose>
        <visual name="visual">
          <geometry>
            <box><size>2.5 0.1 1</size></box>
          </geometry>
          <material>
            <ambient>0.7 0.7 0.7 1</ambient>
            <diffuse>0.7 0.7 0.7 1</diffuse>
          </material>
        </visual>
        <collision name="collision">
          <geometry>
            <box><size>2.5 0.1 1</size></box>
          </geometry>
        </collision>
      </link>

      <link name="right_wall_seg3">
        <pose>4.7678 3.0178 0.5 0 0 1.5708</pose>
        <visual name="visual">
          <geometry>
            <box><size>2.5 0.1 1</size></box>
          </geometry>
          <material>
            <ambient>0.7 0.7 0.7 1</ambient>
            <diffuse>0.7 0.7 0.7 1</diffuse>
          </material>
        </visual>
        <collision name="collision">
          <geometry>
            <box><size>2.5 0.1 1</size></box>
          </geometry>
        </collision>
      </link>
            <joint name="floor_to_left_wall_seg1" type="fixed">
        <parent>floor</parent>
        <child>left_wall_seg1</child>
        <pose>1.0 0.5 0.5 0 0 0</pose>
      </joint>

      <joint name="floor_to_right_wall_seg1" type="fixed">
        <parent>floor</parent>
        <child>right_wall_seg1</child>
        <pose>1.0 -0.5 0.5 0 0 0</pose>
      </joint>

      <joint name="floor_to_left_wall_seg2" type="fixed">
        <parent>floor</parent>
        <child>left_wall_seg2</child>
        <pose>3.0003 1.2875 0.5 0 0 0.7854</pose>
      </joint>

      <joint name="floor_to_right_wall_seg2" type="fixed">
        <parent>floor</parent>
        <child>right_wall_seg2</child>
        <pose>3.6625 0.6053 0.5 0 0 0.7854</pose>
      </joint>

      <joint name="floor_to_left_wall_seg3" type="fixed">
        <parent>floor</parent>
        <child>left_wall_seg3</child>
        <pose>3.7678 3.2678 0.5 0 0 1.5708</pose>
      </joint>

      <joint name="floor_to_right_wall_seg3" type="fixed">
        <parent>floor</parent>
        <child>right_wall_seg3</child>
        <pose>4.7678 3.0178 0.5 0 0 1.5708</pose>
      </joint>


      <pose>0 0 0 0 -0 0</pose>
      <self_collide>false</self_collide>
    </model>
    <light name='sun' type='directional'>
      <pose>0 0 10 0 -0 0</pose>
      <cast_shadows>true</cast_shadows>
      <intensity>1</intensity>
      <direction>-0.5 0.1 -0.9</direction>
      <diffuse>0.8 0.8 0.8 1</diffuse>
      <specular>0.2 0.2 0.2 1</specular>
      <attenuation>
        <range>1000</range>
        <linear>0.01</linear>
        <constant>0.90000000000000002</constant>
        <quadratic>0.001</quadratic>
      </attenuation>
      <spot>
        <inner_angle>0</inner_angle>
        <outer_angle>0</outer_angle>
        <falloff>0</falloff>
      </spot>
    </light>
      <!-- TRACK MODEL: A static model containing walls forming the track -->

  <model name="my_robot" canonical_link='chassis'>
            <pose relative_to='world'>1 0 0 0 0 0</pose>
            <link name="chassis">
                <pose relative_to='__model__'>0 0 0.15 0 0 0</pose>
                <visual name='visual'>
                    <geometry>
                        <cylinder>
                            <radius>0.3</radius>
                            <length>0.1</length>
                        </cylinder>
                    </geometry>
                    <material>
                        <ambient>0.0 0.0 1.0 1</ambient>
                        <diffuse>0.0 0.0 1.0 1</diffuse>
                        <specular>0.0 0.0 1.0 1</specular>
                    </material>
                </visual>

                <collision name='collision'>
                    <geometry>
                        <cylinder>
                            <radius>0.3</radius>
                            <length>0.1</length>
                        </cylinder>
                    </geometry>
                </collision>
                <inertial> <!--inertial properties of the link mass, inertia matix-->
                    <mass>1.14395</mass>
                    <inertia>
                        <ixx>0.095329</ixx>
                        <ixy>0</ixy>
                        <ixz>0</ixz>
                        <iyy>0.381317</iyy>
                        <iyz>0</iyz>
                        <izz>0.476646</izz>
                    </inertia>
                </inertial>
                <sensor name="imu_sensor" type="imu">
                    <always_on>1</always_on>
                    <update_rate>1</update_rate>
                    <visualize>true</visualize>
                    <topic>imu</topic>
                </sensor>
            </link>
            <link name='left_wheel'>
                <pose relative_to="chassis">0 0.3 0 1.5707 0 0</pose>
                <inertial>
                    <mass>1</mass>
                    <inertia>
                        <ixx>0.043333</ixx>
                        <ixy>0</ixy>
                        <ixz>0</ixz>
                        <iyy>0.043333</iyy>
                        <iyz>0</iyz>
                        <izz>0.08</izz>
                    </inertia>
                </inertial>
                <visual name='visual'>
                    <geometry>
                        <cylinder>
                            <radius>0.15</radius>
                            <length>0.05</length>
                        </cylinder>
                    </geometry>
                    <material>
                        <ambient>1.0 0.0 0.0 1</ambient>
                        <diffuse>1.0 0.0 0.0 1</diffuse>
                        <specular>1.0 0.0 0.0 1</specular>
                    </material>
                </visual>
                <collision name='collision'>
                    <geometry>
                        <cylinder>
                            <radius>0.15</radius>
                            <length>0.05</length>
                        </cylinder>
                    </geometry>
                </collision>
            </link>
            <link name='right_wheel'>
                <pose relative_to="chassis">0 -0.3 0 1.5707 0 0</pose>
                <inertial>
                    <mass>1</mass>
                    <inertia>
                        <ixx>0.043333</ixx>
                        <ixy>0</ixy>
                        <ixz>0</ixz>
                        <iyy>0.043333</iyy>
                        <iyz>0</iyz>
                        <izz>0.08</izz>
                    </inertia>
                </inertial>
                <visual name='visual'>
                    <geometry>
                        <cylinder>
                            <radius>0.15</radius>
                            <length>0.05</length>
                        </cylinder>
                    </geometry>
                    <material>
                        <ambient>1.0 0.0 0.0 1</ambient>
                        <diffuse>1.0 0.0 0.0 1</diffuse>
                        <specular>1.0 0.0 0.0 1</specular>
                    </material>
                </visual>
                <collision name='collision'>
                    <geometry>
                        <cylinder>
                            <radius>0.15</radius>
                            <length>0.05</length>
                        </cylinder>
                    </geometry>
                </collision>
            </link>
            <joint name='left_wheel_joint' type='revolute'>
                <pose relative_to='left_wheel'/>
                <parent>chassis</parent>
                <child>left_wheel</child>
                <axis>
                    <xyz expressed_in='__model__'>0 1 0</xyz> <!--can be defined as any frame or even arbitrary frames-->
                    <limit>
                        <lower>-1.79769e+308</lower>    <!--negative infinity-->
                        <upper>1.79769e+308</upper>     <!--positive infinity-->
                    </limit>
                </axis>
            </joint>
            <joint name='right_wheel_joint' type='revolute'>
                <pose relative_to='right_wheel'/>
                <parent>chassis</parent>
                <child>right_wheel</child>
                <axis>
                    <xyz expressed_in='__model__'>0 1 0</xyz> <!--can be defined as any frame or even arbitrary frames-->
                    <limit>
                        <lower>-1.79769e+308</lower>    <!--negative infinity-->
                        <upper>1.79769e+308</upper>     <!--positive infinity-->
                    </limit>
                </axis>
            </joint>
            <frame name="front_caster_frame" attached_to='chassis'>
                <pose>0.2 0 -0.05 0 0 0</pose>
            </frame>
            <link name='front_caster_wheel'>
                <pose relative_to='front_caster_frame'/>
                <inertial>
                    <mass>1</mass>
                    <inertia>
                        <ixx>0.016</ixx>
                        <ixy>0</ixy>
                        <ixz>0</ixz>
                        <iyy>0.016</iyy>
                        <iyz>0</iyz>
                        <izz>0.016</izz>
                    </inertia>
                </inertial>
                <visual name='visual'>
                    <geometry>
                        <sphere>
                            <radius>0.1</radius>
                        </sphere>
                    </geometry>
                    <material>
                        <ambient>0.0 1 0.0 1</ambient>
                        <diffuse>0.0 1 0.0 1</diffuse>
                        <specular>0.0 1 0.0 1</specular>
                    </material>
                </visual>
                <collision name='collision'>
                    <geometry>
                        <sphere>
                            <radius>0.1</radius>
                        </sphere>
                    </geometry>
                </collision>
            </link>
            <joint name='front_caster_wheel_joint' type='ball'>
            <parent>chassis</parent>
            <child>front_caster_wheel</child>
            </joint>
            <frame name="rear_caster_frame" attached_to='chassis'>
                <pose>-0.2 0 -0.05 0 0 0</pose>
            </frame>
            <link name='rear_caster_wheel'>
                <pose relative_to='rear_caster_frame'/>
                <inertial>
                    <mass>1</mass>
                    <inertia>
                        <ixx>0.016</ixx>
                        <ixy>0</ixy>
                        <ixz>0</ixz>
                        <iyy>0.016</iyy>
                        <iyz>0</iyz>
                        <izz>0.016</izz>
                    </inertia>
                </inertial>
                <visual name='visual'>
                    <geometry>
                        <sphere>
                            <radius>0.1</radius>
                        </sphere>
                    </geometry>
                    <material>
                        <ambient>0.0 1 0.0 1</ambient>
                        <diffuse>0.0 1 0.0 1</diffuse>
                        <specular>0.0 1 0.0 1</specular>
                    </material>
                </visual>
                <collision name='collision'>
                    <geometry>
                        <sphere>
                            <radius>0.1</radius>
                        </sphere>
                    </geometry>
                </collision>
            </link>
            <joint name='rear_caster_wheel_joint' type='ball'>
            <parent>chassis</parent>
            <child>rear_caster_wheel</child>
            </joint>   
            <include>
                <uri>robot/components/support.sdf</uri>
                <name>front_left_column</name>
                <pose relative_to="chassis">0.1 0.1 0.125 0 0 0</pose>
            </include> 
            <include>
                <uri>robot/components/support.sdf</uri>
                <name>front_right_column</name>
                <pose relative_to="chassis">0.1 -0.1 0.125 0 0 0</pose>
            </include> 
            <include>
                <uri>robot/components/support.sdf</uri>
                <name>rear_left_column</name>
                <pose relative_to="chassis">-0.1 0.1 0.125 0 0 0</pose>
            </include> 
            <include>
                <uri>robot/components/support.sdf</uri>
                <name>rear_right_column</name>
                <pose relative_to="chassis">-0.1 -0.1 0.125 0 0 0</pose>
            </include>
             <joint name='front_left_column_joint' type='fixed'>
                <parent>chassis</parent>
                <child>front_left_column</child>
            </joint>
            <joint name='front_right_column_joint' type='fixed'>
                <parent>chassis</parent>
                <child>front_right_column</child>
            </joint> 
            <joint name='rear_left_column_joint' type='fixed'>
                <parent>chassis</parent>
                <child>rear_left_column</child>
            </joint> 
            <joint name='rear_right_column_joint' type='fixed'>
                <parent>chassis</parent>
                <child>rear_right_column</child>
            </joint>  
            <link name="plate_2">
                <pose relative_to='chassis'>0 0 0.2 0 0 0</pose>
                <visual name='visual'>
                    <geometry>
                        <cylinder>
                            <radius>0.25</radius>
                            <length>0.05</length>
                        </cylinder>
                    </geometry>
                    <material>
                        <ambient>0.0 0.0 1.0 1</ambient>
                        <diffuse>0.0 0.0 1.0 1</diffuse>
                        <specular>0.0 0.0 1.0 1</specular>
                    </material>
                </visual>

                <collision name='collision'>
                    <geometry>
                        <cylinder>
                            <radius>0.25</radius>
                            <length>0.05</length>
                        </cylinder>
                    </geometry>
                </collision>
                <inertial> 
                    <mass>1.14395</mass>
                    <inertia>
                        <ixx>0.095329</ixx>
                        <ixy>0</ixy>
                        <ixz>0</ixz>
                        <iyy>0.381317</iyy>
                        <iyz>0</iyz>
                        <izz>0.476646</izz>
                    </inertia>
                </inertial>

                <sensor name='gpu_lidar' type='gpu_lidar'>"
                    <pose relative_to='lidar_frame'>0 0 0 0 0 0</pose>
                    <topic>lidar</topic>
                    <update_rate>10</update_rate>
                    <ray>
                        <scan>
                            <horizontal>
                                <samples>640</samples>
                                <resolution>1</resolution>
                                <min_angle>-1.396263</min_angle>
                                <max_angle>1.396263</max_angle>
                            </horizontal>
                            <vertical>
                                <samples>1</samples>
                                <resolution>0.01</resolution>
                                <min_angle>0</min_angle>
                                <max_angle>0</max_angle>
                            </vertical>
                        </scan>
                        <range>
                            <min>0.08</min>
                            <max>10.0</max>
                            <resolution>0.01</resolution>
                        </range>
                    </ray>
                    <always_on>1</always_on>
                    <visualize>true</visualize>
                </sensor> 
            </link>  
            <joint name='plate_2_joint' type='fixed'>
                <parent>chassis</parent>
                <child>plate_2</child>
            </joint>
            <frame name="lidar_frame" attached_to='plate_2'>
                <pose>0 0 0.025 0 0 0</pose>
            </frame>
            <include>
                <uri>file://lidar</uri>
                <name>lidar</name>
                <pose relative_to="plate_2">0 0 0.025 0 0 0</pose>
            </include>
            <joint name='lidar_joint' type='fixed'>
                <parent>plate_2</parent>
                <child>lidar</child>
            </joint>
            <plugin
                filename="libignition-gazebo-diff-drive-system.so"
                name="ignition::gazebo::systems::DiffDrive">
                <left_joint>left_wheel_joint</left_joint>
                <right_joint>right_wheel_joint</right_joint>
                <wheel_separation>0.6</wheel_separation>
                <wheel_radius>0.15</wheel_radius>
                <odom_publish_frequency>1</odom_publish_frequency>
                <topic>cmd_vel</topic>
            </plugin>
            <plugin filename="libignition-gazebo-triggered-publisher-system.so"
                    name="ignition::gazebo::systems::TriggeredPublisher">
                <input type="ignition.msgs.Int32" topic="/keyboard/keypress">
                    <match field="data">87</match>
                </input>
                <output type="ignition.msgs.Twist" topic="/cmd_vel">
                    linear: {x: 0.5}, angular: {z: 0.0}
                </output>
            </plugin>
            <plugin filename="libignition-gazebo-triggered-publisher-system.so"
                    name="ignition::gazebo::systems::TriggeredPublisher">
                <input type="ignition.msgs.Int32" topic="/keyboard/keypress">
                    <match field="data">65</match>
                </input>
                <output type="ignition.msgs.Twist" topic="/cmd_vel">
                    linear: {x: 0.0}, angular: {z: 0.5}
                </output>
            </plugin>
            <plugin filename="libignition-gazebo-triggered-publisher-system.so"
                    name="ignition::gazebo::systems::TriggeredPublisher">
                <input type="ignition.msgs.Int32" topic="/keyboard/keypress">
                    <match field="data">83</match>
                </input>
                <output type="ignition.msgs.Twist" topic="/cmd_vel">
                    linear: {x: -0.5}, angular: {z: 0.0}
                </output>
            </plugin>
            <plugin filename="libignition-gazebo-triggered-publisher-system.so"
                    name="ignition::gazebo::systems::TriggeredPublisher">
                <input type="ignition.msgs.Int32" topic="/keyboard/keypress">
                    <match field="data">68</match>
                </input>
                <output type="ignition.msgs.Twist" topic="/cmd_vel">
                    linear: {x: 0.0}, angular: {z: -0.5}
                </output>
            </plugin>
            <plugin filename="libignition-gazebo-triggered-publisher-system.so"
                    name="ignition::gazebo::systems::TriggeredPublisher">
                <input type="ignition.msgs.Int32" topic="/keyboard/keypress">
                    <match field="data">70</match>
                </input>
                <output type="ignition.msgs.Twist" topic="/cmd_vel">
                    linear: {x: 0.0}, angular: {z: 0.0}
                </output>
            </plugin>
        </model>
  </world>
</sdf>